package com.bloodguy.bloodcraft.biome.features;

import java.util.Random;

import com.bloodguy.bloodcraft.BloodCraftMod;

import net.minecraft.init.Blocks;
import net.minecraft.init.Items;
import net.minecraft.tileentity.TileEntityChest;
import net.minecraft.util.WeightedRandomChestContent;
import net.minecraft.world.World;

public class DesolationStructure {
	private static Random rand;
	
	public static final WeightedRandomChestContent[] cryptChestContent = new WeightedRandomChestContent[] {new WeightedRandomChestContent(Items.bow, 150, 1, 1, 10), new WeightedRandomChestContent(Items.arrow, 0, 10, 15, 15)};
	
	public static void GenerateLavalOreFall(World par1World, int x, int y, int z)
	{
		par1World.setBlock(x + 0, y + 0, z + 0, Blocks.cobblestone, 0, 3);
		par1World.setBlock(x + 1, y + 0, z + 0, Blocks.cobblestone, 0, 3);
		par1World.setBlock(x + 2, y + 0, z + 0, Blocks.cobblestone, 0, 3);
		par1World.setBlock(x + 3, y + 0, z + 0, Blocks.cobblestone, 0, 3);
		par1World.setBlock(x + 4, y + 0, z + 0, Blocks.cobblestone, 0, 3);
		par1World.setBlock(x + 0, y + 0, z + 1, Blocks.cobblestone, 0, 3);
		par1World.setBlock(x + 1, y + 0, z + 1, Blocks.cobblestone, 0, 3);
		par1World.setBlock(x + 2, y + 0, z + 1, Blocks.cobblestone, 0, 3);
		par1World.setBlock(x + 3, y + 0, z + 1, Blocks.cobblestone, 0, 3);
		par1World.setBlock(x + 4, y + 0, z + 1, Blocks.cobblestone, 0, 3);
		par1World.setBlock(x + 0, y + 0, z + 2, Blocks.cobblestone, 0, 3);
		par1World.setBlock(x + 1, y + 0, z + 2, Blocks.cobblestone, 0, 3);
		par1World.setBlock(x + 2, y + 0, z + 2, Blocks.cobblestone, 0, 3);
		par1World.setBlock(x + 3, y + 0, z + 2, Blocks.cobblestone, 0, 3);
		par1World.setBlock(x + 4, y + 0, z + 2, Blocks.cobblestone, 0, 3);
		par1World.setBlock(x + 0, y + 0, z + 3, Blocks.cobblestone, 0, 3);
		par1World.setBlock(x + 1, y + 0, z + 3, Blocks.cobblestone, 0, 3);
		par1World.setBlock(x + 2, y + 0, z + 3, Blocks.cobblestone, 0, 3);
		par1World.setBlock(x + 3, y + 0, z + 3, Blocks.cobblestone, 0, 3);
		par1World.setBlock(x + 4, y + 0, z + 3, Blocks.cobblestone, 0, 3);
		par1World.setBlock(x + 0, y + 0, z + 4, Blocks.cobblestone, 0, 3);
		par1World.setBlock(x + 1, y + 0, z + 4, Blocks.cobblestone, 0, 3);
		par1World.setBlock(x + 2, y + 0, z + 4, Blocks.cobblestone, 0, 3);
		par1World.setBlock(x + 3, y + 0, z + 4, Blocks.cobblestone, 0, 3);
		par1World.setBlock(x + 4, y + 0, z + 4, Blocks.cobblestone, 0, 3);
		par1World.setBlock(x + 0, y + 1, z + 0, Blocks.cobblestone, 0, 3);
		par1World.setBlock(x + 1, y + 1, z + 0, Blocks.cobblestone, 0, 3);
		par1World.setBlock(x + 2, y + 1, z + 0, Blocks.cobblestone, 0, 3);
		par1World.setBlock(x + 3, y + 1, z + 0, Blocks.cobblestone, 0, 3);
		par1World.setBlock(x + 4, y + 1, z + 0, Blocks.cobblestone, 0, 3);
		par1World.setBlock(x + 0, y + 1, z + 1, Blocks.cobblestone, 0, 3);
		par1World.setBlock(x + 1, y + 1, z + 1, Blocks.cobblestone, 0, 3);
		par1World.setBlock(x + 2, y + 1, z + 1, Blocks.cobblestone, 0, 3);
		par1World.setBlock(x + 3, y + 1, z + 1, Blocks.cobblestone, 0, 3);
		par1World.setBlock(x + 4, y + 1, z + 1, Blocks.cobblestone, 0, 3);
		par1World.setBlock(x + 0, y + 1, z + 2, Blocks.cobblestone, 0, 3);
		par1World.setBlock(x + 1, y + 1, z + 2, Blocks.cobblestone, 0, 3);
		par1World.setBlock(x + 2, y + 1, z + 2, Blocks.cobblestone, 0, 3);
		par1World.setBlock(x + 3, y + 1, z + 2, Blocks.cobblestone, 0, 3);
		par1World.setBlock(x + 4, y + 1, z + 2, Blocks.cobblestone, 0, 3);
		par1World.setBlock(x + 0, y + 1, z + 3, Blocks.cobblestone, 0, 3);
		par1World.setBlock(x + 1, y + 1, z + 3, Blocks.cobblestone, 0, 3);
		par1World.setBlock(x + 2, y + 1, z + 3, Blocks.cobblestone, 0, 3);
		par1World.setBlock(x + 3, y + 1, z + 3, Blocks.cobblestone, 0, 3);
		par1World.setBlock(x + 4, y + 1, z + 3, Blocks.cobblestone, 0, 3);
		par1World.setBlock(x + 0, y + 1, z + 4, Blocks.cobblestone, 0, 3);
		par1World.setBlock(x + 1, y + 1, z + 4, Blocks.cobblestone, 0, 3);
		par1World.setBlock(x + 2, y + 1, z + 4, Blocks.cobblestone, 0, 3);
		par1World.setBlock(x + 3, y + 1, z + 4, Blocks.cobblestone, 0, 3);
		par1World.setBlock(x + 4, y + 1, z + 4, Blocks.cobblestone, 0, 3);
		par1World.setBlock(x + 0, y + 2, z + 0, Blocks.cobblestone, 0, 3);
		par1World.setBlock(x + 1, y + 2, z + 0, Blocks.cobblestone, 0, 3);
		par1World.setBlock(x + 2, y + 2, z + 0, Blocks.cobblestone, 0, 3);
		par1World.setBlock(x + 3, y + 2, z + 0, Blocks.cobblestone, 0, 3);
		par1World.setBlock(x + 4, y + 2, z + 0, Blocks.cobblestone, 0, 3);
		par1World.setBlock(x + 0, y + 2, z + 1, Blocks.cobblestone, 0, 3);
		par1World.setBlock(x + 1, y + 2, z + 1, Blocks.lava, 12, 3);
		par1World.setBlock(x + 2, y + 2, z + 1, Blocks.cobblestone, 0, 3);
		par1World.setBlock(x + 3, y + 2, z + 1, Blocks.lava, 12, 3);
		par1World.setBlock(x + 4, y + 2, z + 1, Blocks.cobblestone, 0, 3);
		par1World.setBlock(x + 0, y + 2, z + 2, Blocks.cobblestone, 0, 3);
		par1World.setBlock(x + 1, y + 2, z + 2, Blocks.cobblestone, 0, 3);
		par1World.setBlock(x + 2, y + 2, z + 2, BloodCraftMod.DesolatedOre, 0, 3);
		par1World.setBlock(x + 3, y + 2, z + 2, Blocks.cobblestone, 0, 3);
		par1World.setBlock(x + 4, y + 2, z + 2, Blocks.cobblestone, 0, 3);
		par1World.setBlock(x + 0, y + 2, z + 3, Blocks.cobblestone, 0, 3);
		par1World.setBlock(x + 1, y + 2, z + 3, Blocks.lava, 12, 3);
		par1World.setBlock(x + 2, y + 2, z + 3, Blocks.cobblestone, 0, 3);
		par1World.setBlock(x + 3, y + 2, z + 3, Blocks.lava, 12, 3);
		par1World.setBlock(x + 4, y + 2, z + 3, Blocks.cobblestone, 0, 3);
		par1World.setBlock(x + 0, y + 2, z + 4, Blocks.cobblestone, 0, 3);
		par1World.setBlock(x + 1, y + 2, z + 4, Blocks.cobblestone, 0, 3);
		par1World.setBlock(x + 2, y + 2, z + 4, Blocks.cobblestone, 0, 3);
		par1World.setBlock(x + 3, y + 2, z + 4, Blocks.cobblestone, 0, 3);
		par1World.setBlock(x + 4, y + 2, z + 4, Blocks.cobblestone, 0, 3);
		par1World.setBlock(x + 0, y + 3, z + 0, Blocks.air, 0, 3);
		par1World.setBlock(x + 1, y + 3, z + 0, Blocks.air, 0, 3);
		par1World.setBlock(x + 2, y + 3, z + 0, Blocks.air, 0, 3);
		par1World.setBlock(x + 3, y + 3, z + 0, Blocks.air, 0, 3);
		par1World.setBlock(x + 4, y + 3, z + 0, Blocks.air, 0, 3);
		par1World.setBlock(x + 0, y + 3, z + 1, Blocks.air, 0, 3);
		par1World.setBlock(x + 1, y + 3, z + 1, Blocks.lava, 12, 3);
		par1World.setBlock(x + 2, y + 3, z + 1, Blocks.air, 0, 3);
		par1World.setBlock(x + 3, y + 3, z + 1, Blocks.lava, 12, 3);
		par1World.setBlock(x + 4, y + 3, z + 1, Blocks.air, 0, 3);
		par1World.setBlock(x + 0, y + 3, z + 2, Blocks.air, 0, 3);
		par1World.setBlock(x + 1, y + 3, z + 2, Blocks.air, 0, 3);
		par1World.setBlock(x + 2, y + 3, z + 2, Blocks.obsidian, 0, 3);
		par1World.setBlock(x + 3, y + 3, z + 2, Blocks.air, 0, 3);
		par1World.setBlock(x + 4, y + 3, z + 2, Blocks.air, 0, 3);
		par1World.setBlock(x + 0, y + 3, z + 3, Blocks.air, 0, 3);
		par1World.setBlock(x + 1, y + 3, z + 3, Blocks.lava, 12, 3);
		par1World.setBlock(x + 2, y + 3, z + 3, Blocks.air, 0, 3);
		par1World.setBlock(x + 3, y + 3, z + 3, Blocks.lava, 12, 3);
		par1World.setBlock(x + 4, y + 3, z + 3, Blocks.air, 0, 3);
		par1World.setBlock(x + 0, y + 3, z + 4, Blocks.air, 0, 3);
		par1World.setBlock(x + 1, y + 3, z + 4, Blocks.air, 0, 3);
		par1World.setBlock(x + 2, y + 3, z + 4, Blocks.air, 0, 3);
		par1World.setBlock(x + 3, y + 3, z + 4, Blocks.air, 0, 3);
		par1World.setBlock(x + 4, y + 3, z + 4, Blocks.air, 0, 3);
		par1World.setBlock(x + 0, y + 4, z + 0, Blocks.air, 0, 3);
		par1World.setBlock(x + 1, y + 4, z + 0, Blocks.air, 0, 3);
		par1World.setBlock(x + 2, y + 4, z + 0, Blocks.air, 0, 3);
		par1World.setBlock(x + 3, y + 4, z + 0, Blocks.air, 0, 3);
		par1World.setBlock(x + 4, y + 4, z + 0, Blocks.air, 0, 3);
		par1World.setBlock(x + 0, y + 4, z + 1, Blocks.air, 0, 3);
		par1World.setBlock(x + 1, y + 4, z + 1, Blocks.lava, 12, 3);
		par1World.setBlock(x + 2, y + 4, z + 1, Blocks.air, 0, 3);
		par1World.setBlock(x + 3, y + 4, z + 1, Blocks.lava, 12, 3);
		par1World.setBlock(x + 4, y + 4, z + 1, Blocks.air, 0, 3);
		par1World.setBlock(x + 0, y + 4, z + 2, Blocks.air, 0, 3);
		par1World.setBlock(x + 1, y + 4, z + 2, Blocks.air, 0, 3);
		par1World.setBlock(x + 2, y + 4, z + 2, Blocks.obsidian, 0, 3);
		par1World.setBlock(x + 3, y + 4, z + 2, Blocks.air, 0, 3);
		par1World.setBlock(x + 4, y + 4, z + 2, Blocks.air, 0, 3);
		par1World.setBlock(x + 0, y + 4, z + 3, Blocks.air, 0, 3);
		par1World.setBlock(x + 1, y + 4, z + 3, Blocks.lava, 12, 3);
		par1World.setBlock(x + 2, y + 4, z + 3, Blocks.air, 0, 3);
		par1World.setBlock(x + 3, y + 4, z + 3, Blocks.lava, 12, 3);
		par1World.setBlock(x + 4, y + 4, z + 3, Blocks.air, 0, 3);
		par1World.setBlock(x + 0, y + 4, z + 4, Blocks.air, 0, 3);
		par1World.setBlock(x + 1, y + 4, z + 4, Blocks.air, 0, 3);
		par1World.setBlock(x + 2, y + 4, z + 4, Blocks.air, 0, 3);
		par1World.setBlock(x + 3, y + 4, z + 4, Blocks.air, 0, 3);
		par1World.setBlock(x + 4, y + 4, z + 4, Blocks.air, 0, 3);
		par1World.setBlock(x + 0, y + 5, z + 0, Blocks.air, 0, 3);
		par1World.setBlock(x + 1, y + 5, z + 0, Blocks.air, 0, 3);
		par1World.setBlock(x + 2, y + 5, z + 0, Blocks.air, 0, 3);
		par1World.setBlock(x + 3, y + 5, z + 0, Blocks.air, 0, 3);
		par1World.setBlock(x + 4, y + 5, z + 0, Blocks.air, 0, 3);
		par1World.setBlock(x + 0, y + 5, z + 1, Blocks.air, 0, 3);
		par1World.setBlock(x + 1, y + 5, z + 1, Blocks.lava, 12, 3);
		par1World.setBlock(x + 2, y + 5, z + 1, Blocks.air, 0, 3);
		par1World.setBlock(x + 3, y + 5, z + 1, Blocks.lava, 12, 3);
		par1World.setBlock(x + 4, y + 5, z + 1, Blocks.air, 0, 3);
		par1World.setBlock(x + 0, y + 5, z + 2, Blocks.air, 0, 3);
		par1World.setBlock(x + 1, y + 5, z + 2, Blocks.air, 0, 3);
		par1World.setBlock(x + 2, y + 5, z + 2, Blocks.obsidian, 0, 3);
		par1World.setBlock(x + 3, y + 5, z + 2, Blocks.air, 0, 3);
		par1World.setBlock(x + 4, y + 5, z + 2, Blocks.air, 0, 3);
		par1World.setBlock(x + 0, y + 5, z + 3, Blocks.air, 0, 3);
		par1World.setBlock(x + 1, y + 5, z + 3, Blocks.lava, 12, 3);
		par1World.setBlock(x + 2, y + 5, z + 3, Blocks.air, 0, 3);
		par1World.setBlock(x + 3, y + 5, z + 3, Blocks.lava, 12, 3);
		par1World.setBlock(x + 4, y + 5, z + 3, Blocks.air, 0, 3);
		par1World.setBlock(x + 0, y + 5, z + 4, Blocks.air, 0, 3);
		par1World.setBlock(x + 1, y + 5, z + 4, Blocks.air, 0, 3);
		par1World.setBlock(x + 2, y + 5, z + 4, Blocks.air, 0, 3);
		par1World.setBlock(x + 3, y + 5, z + 4, Blocks.air, 0, 3);
		par1World.setBlock(x + 4, y + 5, z + 4, Blocks.air, 0, 3);
		par1World.setBlock(x + 0, y + 6, z + 0, Blocks.air, 0, 3);
		par1World.setBlock(x + 1, y + 6, z + 0, Blocks.air, 0, 3);
		par1World.setBlock(x + 2, y + 6, z + 0, Blocks.air, 0, 3);
		par1World.setBlock(x + 3, y + 6, z + 0, Blocks.air, 0, 3);
		par1World.setBlock(x + 4, y + 6, z + 0, Blocks.air, 0, 3);
		par1World.setBlock(x + 0, y + 6, z + 1, Blocks.air, 0, 3);
		par1World.setBlock(x + 1, y + 6, z + 1, Blocks.lava, 12, 3);
		par1World.setBlock(x + 2, y + 6, z + 1, Blocks.air, 0, 3);
		par1World.setBlock(x + 3, y + 6, z + 1, Blocks.lava, 12, 3);
		par1World.setBlock(x + 4, y + 6, z + 1, Blocks.air, 0, 3);
		par1World.setBlock(x + 0, y + 6, z + 2, Blocks.air, 0, 3);
		par1World.setBlock(x + 1, y + 6, z + 2, Blocks.air, 0, 3);
		par1World.setBlock(x + 2, y + 6, z + 2, Blocks.obsidian, 0, 3);
		par1World.setBlock(x + 3, y + 6, z + 2, Blocks.air, 0, 3);
		par1World.setBlock(x + 4, y + 6, z + 2, Blocks.air, 0, 3);
		par1World.setBlock(x + 0, y + 6, z + 3, Blocks.air, 0, 3);
		par1World.setBlock(x + 1, y + 6, z + 3, Blocks.lava, 12, 3);
		par1World.setBlock(x + 2, y + 6, z + 3, Blocks.air, 0, 3);
		par1World.setBlock(x + 3, y + 6, z + 3, Blocks.lava, 12, 3);
		par1World.setBlock(x + 4, y + 6, z + 3, Blocks.air, 0, 3);
		par1World.setBlock(x + 0, y + 6, z + 4, Blocks.air, 0, 3);
		par1World.setBlock(x + 1, y + 6, z + 4, Blocks.air, 0, 3);
		par1World.setBlock(x + 2, y + 6, z + 4, Blocks.air, 0, 3);
		par1World.setBlock(x + 3, y + 6, z + 4, Blocks.air, 0, 3);
		par1World.setBlock(x + 4, y + 6, z + 4, Blocks.air, 0, 3);
		par1World.setBlock(x + 0, y + 7, z + 0, Blocks.air, 0, 3);
		par1World.setBlock(x + 1, y + 7, z + 0, Blocks.air, 0, 3);
		par1World.setBlock(x + 2, y + 7, z + 0, Blocks.air, 0, 3);
		par1World.setBlock(x + 3, y + 7, z + 0, Blocks.air, 0, 3);
		par1World.setBlock(x + 4, y + 7, z + 0, Blocks.air, 0, 3);
		par1World.setBlock(x + 0, y + 7, z + 1, Blocks.air, 0, 3);
		par1World.setBlock(x + 1, y + 7, z + 1, Blocks.lava, 12, 3);
		par1World.setBlock(x + 2, y + 7, z + 1, Blocks.air, 0, 3);
		par1World.setBlock(x + 3, y + 7, z + 1, Blocks.lava, 12, 3);
		par1World.setBlock(x + 4, y + 7, z + 1, Blocks.air, 0, 3);
		par1World.setBlock(x + 0, y + 7, z + 2, Blocks.air, 0, 3);
		par1World.setBlock(x + 1, y + 7, z + 2, Blocks.air, 0, 3);
		par1World.setBlock(x + 2, y + 7, z + 2, Blocks.obsidian, 0, 3);
		par1World.setBlock(x + 3, y + 7, z + 2, Blocks.air, 0, 3);
		par1World.setBlock(x + 4, y + 7, z + 2, Blocks.air, 0, 3);
		par1World.setBlock(x + 0, y + 7, z + 3, Blocks.air, 0, 3);
		par1World.setBlock(x + 1, y + 7, z + 3, Blocks.lava, 12, 3);
		par1World.setBlock(x + 2, y + 7, z + 3, Blocks.air, 0, 3);
		par1World.setBlock(x + 3, y + 7, z + 3, Blocks.lava, 12, 3);
		par1World.setBlock(x + 4, y + 7, z + 3, Blocks.air, 0, 3);
		par1World.setBlock(x + 0, y + 7, z + 4, Blocks.air, 0, 3);
		par1World.setBlock(x + 1, y + 7, z + 4, Blocks.air, 0, 3);
		par1World.setBlock(x + 2, y + 7, z + 4, Blocks.air, 0, 3);
		par1World.setBlock(x + 3, y + 7, z + 4, Blocks.air, 0, 3);
		par1World.setBlock(x + 4, y + 7, z + 4, Blocks.air, 0, 3);
		par1World.setBlock(x + 0, y + 8, z + 0, Blocks.air, 0, 3);
		par1World.setBlock(x + 1, y + 8, z + 0, Blocks.air, 0, 3);
		par1World.setBlock(x + 2, y + 8, z + 0, Blocks.air, 0, 3);
		par1World.setBlock(x + 3, y + 8, z + 0, Blocks.air, 0, 3);
		par1World.setBlock(x + 4, y + 8, z + 0, Blocks.air, 0, 3);
		par1World.setBlock(x + 0, y + 8, z + 1, Blocks.air, 0, 3);
		par1World.setBlock(x + 1, y + 8, z + 1, Blocks.lava, 12, 3);
		par1World.setBlock(x + 2, y + 8, z + 1, Blocks.air, 0, 3);
		par1World.setBlock(x + 3, y + 8, z + 1, Blocks.lava, 12, 3);
		par1World.setBlock(x + 4, y + 8, z + 1, Blocks.air, 0, 3);
		par1World.setBlock(x + 0, y + 8, z + 2, Blocks.air, 0, 3);
		par1World.setBlock(x + 1, y + 8, z + 2, Blocks.air, 0, 3);
		par1World.setBlock(x + 2, y + 8, z + 2, Blocks.obsidian, 0, 3);
		par1World.setBlock(x + 3, y + 8, z + 2, Blocks.air, 0, 3);
		par1World.setBlock(x + 4, y + 8, z + 2, Blocks.air, 0, 3);
		par1World.setBlock(x + 0, y + 8, z + 3, Blocks.air, 0, 3);
		par1World.setBlock(x + 1, y + 8, z + 3, Blocks.lava, 12, 3);
		par1World.setBlock(x + 2, y + 8, z + 3, Blocks.air, 0, 3);
		par1World.setBlock(x + 3, y + 8, z + 3, Blocks.lava, 12, 3);
		par1World.setBlock(x + 4, y + 8, z + 3, Blocks.air, 0, 3);
		par1World.setBlock(x + 0, y + 8, z + 4, Blocks.air, 0, 3);
		par1World.setBlock(x + 1, y + 8, z + 4, Blocks.air, 0, 3);
		par1World.setBlock(x + 2, y + 8, z + 4, Blocks.air, 0, 3);
		par1World.setBlock(x + 3, y + 8, z + 4, Blocks.air, 0, 3);
		par1World.setBlock(x + 4, y + 8, z + 4, Blocks.air, 0, 3);
		par1World.setBlock(x + 0, y + 9, z + 0, Blocks.cobblestone, 0, 3);
		par1World.setBlock(x + 1, y + 9, z + 0, Blocks.cobblestone, 0, 3);
		par1World.setBlock(x + 2, y + 9, z + 0, Blocks.cobblestone, 0, 3);
		par1World.setBlock(x + 3, y + 9, z + 0, Blocks.cobblestone, 0, 3);
		par1World.setBlock(x + 4, y + 9, z + 0, Blocks.cobblestone, 0, 3);
		par1World.setBlock(x + 0, y + 9, z + 1, Blocks.cobblestone, 0, 3);
		par1World.setBlock(x + 1, y + 9, z + 1, Blocks.lava, 12, 3);
		par1World.setBlock(x + 2, y + 9, z + 1, Blocks.cobblestone, 0, 3);
		par1World.setBlock(x + 3, y + 9, z + 1, Blocks.lava, 12, 3);
		par1World.setBlock(x + 4, y + 9, z + 1, Blocks.cobblestone, 0, 3);
		par1World.setBlock(x + 0, y + 9, z + 2, Blocks.cobblestone, 0, 3);
		par1World.setBlock(x + 1, y + 9, z + 2, Blocks.cobblestone, 0, 3);
		par1World.setBlock(x + 2, y + 9, z + 2, Blocks.cobblestone, 0, 3);
		par1World.setBlock(x + 3, y + 9, z + 2, Blocks.cobblestone, 0, 3);
		par1World.setBlock(x + 4, y + 9, z + 2, Blocks.cobblestone, 0, 3);
		par1World.setBlock(x + 0, y + 9, z + 3, Blocks.cobblestone, 0, 3);
		par1World.setBlock(x + 1, y + 9, z + 3, Blocks.lava, 12, 3);
		par1World.setBlock(x + 2, y + 9, z + 3, Blocks.cobblestone, 0, 3);
		par1World.setBlock(x + 3, y + 9, z + 3, Blocks.lava, 12, 3);
		par1World.setBlock(x + 4, y + 9, z + 3, Blocks.cobblestone, 0, 3);
		par1World.setBlock(x + 0, y + 9, z + 4, Blocks.cobblestone, 0, 3);
		par1World.setBlock(x + 1, y + 9, z + 4, Blocks.cobblestone, 0, 3);
		par1World.setBlock(x + 2, y + 9, z + 4, Blocks.cobblestone, 0, 3);
		par1World.setBlock(x + 3, y + 9, z + 4, Blocks.cobblestone, 0, 3);
		par1World.setBlock(x + 4, y + 9, z + 4, Blocks.cobblestone, 0, 3);
		par1World.setBlock(x + 0, y + 10, z + 0, Blocks.cobblestone, 0, 3);
		par1World.setBlock(x + 1, y + 10, z + 0, Blocks.cobblestone, 0, 3);
		par1World.setBlock(x + 2, y + 10, z + 0, Blocks.cobblestone, 0, 3);
		par1World.setBlock(x + 3, y + 10, z + 0, Blocks.cobblestone, 0, 3);
		par1World.setBlock(x + 4, y + 10, z + 0, Blocks.cobblestone, 0, 3);
		par1World.setBlock(x + 0, y + 10, z + 1, Blocks.cobblestone, 0, 3);
		par1World.setBlock(x + 1, y + 10, z + 1, Blocks.lava, 4, 3);
		par1World.setBlock(x + 2, y + 10, z + 1, Blocks.lava, 2, 3);
		par1World.setBlock(x + 3, y + 10, z + 1, Blocks.lava, 4, 3);
		par1World.setBlock(x + 4, y + 10, z + 1, Blocks.cobblestone, 0, 3);
		par1World.setBlock(x + 0, y + 10, z + 2, Blocks.cobblestone, 0, 3);
		par1World.setBlock(x + 1, y + 10, z + 2, Blocks.lava, 2, 3);
		par1World.setBlock(x + 2, y + 10, z + 2, Blocks.lava, 0, 3);
		par1World.setBlock(x + 3, y + 10, z + 2, Blocks.lava, 2, 3);
		par1World.setBlock(x + 4, y + 10, z + 2, Blocks.cobblestone, 0, 3);
		par1World.setBlock(x + 0, y + 10, z + 3, Blocks.cobblestone, 0, 3);
		par1World.setBlock(x + 1, y + 10, z + 3, Blocks.lava, 4, 3);
		par1World.setBlock(x + 2, y + 10, z + 3, Blocks.lava, 2, 3);
		par1World.setBlock(x + 3, y + 10, z + 3, Blocks.lava, 4, 3);
		par1World.setBlock(x + 4, y + 10, z + 3, Blocks.cobblestone, 0, 3);
		par1World.setBlock(x + 0, y + 10, z + 4, Blocks.cobblestone, 0, 3);
		par1World.setBlock(x + 1, y + 10, z + 4, Blocks.cobblestone, 0, 3);
		par1World.setBlock(x + 2, y + 10, z + 4, Blocks.cobblestone, 0, 3);
		par1World.setBlock(x + 3, y + 10, z + 4, Blocks.cobblestone, 0, 3);
		par1World.setBlock(x + 4, y + 10, z + 4, Blocks.cobblestone, 0, 3);
		par1World.setBlock(x + 0, y + 11, z + 0, BloodCraftMod.TombStoneB, 0, 3);
		par1World.setBlock(x + 1, y + 11, z + 0, Blocks.air, 0, 3);
		par1World.setBlock(x + 2, y + 11, z + 0, Blocks.air, 0, 3);
		par1World.setBlock(x + 3, y + 11, z + 0, Blocks.air, 0, 3);
		par1World.setBlock(x + 4, y + 11, z + 0, BloodCraftMod.TombStoneB, 0, 3);
		par1World.setBlock(x + 0, y + 11, z + 1, Blocks.air, 0, 3);
		par1World.setBlock(x + 1, y + 11, z + 1, Blocks.air, 0, 3);
		par1World.setBlock(x + 2, y + 11, z + 1, Blocks.air, 0, 3);
		par1World.setBlock(x + 3, y + 11, z + 1, Blocks.air, 0, 3);
		par1World.setBlock(x + 4, y + 11, z + 1, Blocks.air, 0, 3);
		par1World.setBlock(x + 0, y + 11, z + 2, Blocks.air, 0, 3);
		par1World.setBlock(x + 1, y + 11, z + 2, Blocks.air, 0, 3);
		par1World.setBlock(x + 2, y + 11, z + 2, Blocks.air, 0, 3);
		par1World.setBlock(x + 3, y + 11, z + 2, Blocks.air, 0, 3);
		par1World.setBlock(x + 4, y + 11, z + 2, Blocks.air, 0, 3);
		par1World.setBlock(x + 0, y + 11, z + 3, Blocks.air, 0, 3);
		par1World.setBlock(x + 1, y + 11, z + 3, Blocks.air, 0, 3);
		par1World.setBlock(x + 2, y + 11, z + 3, Blocks.air, 0, 3);
		par1World.setBlock(x + 3, y + 11, z + 3, Blocks.air, 0, 3);
		par1World.setBlock(x + 4, y + 11, z + 3, Blocks.air, 0, 3);
		par1World.setBlock(x + 0, y + 11, z + 4, BloodCraftMod.TombStoneB, 0, 3);
		par1World.setBlock(x + 1, y + 11, z + 4, Blocks.air, 0, 3);
		par1World.setBlock(x + 2, y + 11, z + 4, Blocks.air, 0, 3);
		par1World.setBlock(x + 3, y + 11, z + 4, Blocks.air, 0, 3);
		par1World.setBlock(x + 4, y + 11, z + 4, BloodCraftMod.TombStoneB, 0, 3);
	}
		
	public static void GenerateCrypt(World par1World, int x, int y, int z)
	{
		par1World.setBlock(x + 0, y + 0, z + 0, BloodCraftMod.DesolatedBrick, 0, 3);
		par1World.setBlock(x + 1, y + 0, z + 0, BloodCraftMod.DesolatedBrick, 0, 3);
		par1World.setBlock(x + 2, y + 0, z + 0, BloodCraftMod.DesolatedBrick, 0, 3);
		par1World.setBlock(x + 3, y + 0, z + 0, BloodCraftMod.DesolatedBrick, 0, 3);
		par1World.setBlock(x + 4, y + 0, z + 0, BloodCraftMod.DesolatedBrick, 0, 3);
		par1World.setBlock(x + 0, y + 0, z + 1, BloodCraftMod.DesolatedBrick, 0, 3);
		par1World.setBlock(x + 1, y + 0, z + 1, BloodCraftMod.DesolatedBrick, 0, 3);
		par1World.setBlock(x + 2, y + 0, z + 1, BloodCraftMod.DesolatedBrick, 0, 3);
		par1World.setBlock(x + 3, y + 0, z + 1, BloodCraftMod.DesolatedBrick, 0, 3);
		par1World.setBlock(x + 4, y + 0, z + 1, BloodCraftMod.DesolatedBrick, 0, 3);
		par1World.setBlock(x + 0, y + 0, z + 2, BloodCraftMod.DesolatedBrick, 0, 3);
		par1World.setBlock(x + 1, y + 0, z + 2, BloodCraftMod.DesolatedBrick, 0, 3);
		par1World.setBlock(x + 2, y + 0, z + 2, BloodCraftMod.DesolatedBrick, 0, 3);
		par1World.setBlock(x + 3, y + 0, z + 2, BloodCraftMod.DesolatedBrick, 0, 3);
		par1World.setBlock(x + 4, y + 0, z + 2, BloodCraftMod.DesolatedBrick, 0, 3);
		par1World.setBlock(x + 0, y + 0, z + 3, BloodCraftMod.DesolatedBrick, 0, 3);
		par1World.setBlock(x + 1, y + 0, z + 3, BloodCraftMod.DesolatedBrick, 0, 3);
		par1World.setBlock(x + 2, y + 0, z + 3, BloodCraftMod.DesolatedBrick, 0, 3);
		par1World.setBlock(x + 3, y + 0, z + 3, BloodCraftMod.DesolatedBrick, 0, 3);
		par1World.setBlock(x + 4, y + 0, z + 3, BloodCraftMod.DesolatedBrick, 0, 3);
		par1World.setBlock(x + 0, y + 0, z + 4, BloodCraftMod.DesolatedBrick, 0, 3);
		par1World.setBlock(x + 1, y + 0, z + 4, BloodCraftMod.DesolatedBrick, 0, 3);
		par1World.setBlock(x + 2, y + 0, z + 4, BloodCraftMod.DesolatedBrick, 0, 3);
		par1World.setBlock(x + 3, y + 0, z + 4, BloodCraftMod.DesolatedBrick, 0, 3);
		par1World.setBlock(x + 4, y + 0, z + 4, BloodCraftMod.DesolatedBrick, 0, 3);
		par1World.setBlock(x + 0, y + 0, z + 5, BloodCraftMod.DesolatedBrick, 0, 3);
		par1World.setBlock(x + 1, y + 0, z + 5, BloodCraftMod.DesolatedBrick, 0, 3);
		par1World.setBlock(x + 2, y + 0, z + 5, BloodCraftMod.DesolatedBrick, 0, 3);
		par1World.setBlock(x + 3, y + 0, z + 5, BloodCraftMod.DesolatedBrick, 0, 3);
		par1World.setBlock(x + 4, y + 0, z + 5, BloodCraftMod.DesolatedBrick, 0, 3);
		par1World.setBlock(x + 0, y + 0, z + 6, BloodCraftMod.DesolatedBrick, 0, 3);
		par1World.setBlock(x + 1, y + 0, z + 6, BloodCraftMod.DesolatedBrick, 0, 3);
		par1World.setBlock(x + 2, y + 0, z + 6, BloodCraftMod.DesolatedBrick, 0, 3);
		par1World.setBlock(x + 3, y + 0, z + 6, BloodCraftMod.DesolatedBrick, 0, 3);
		par1World.setBlock(x + 4, y + 0, z + 6, BloodCraftMod.DesolatedBrick, 0, 3);
		par1World.setBlock(x + 0, y + 0, z + 7, BloodCraftMod.DesolatedBrick, 0, 3);
		par1World.setBlock(x + 1, y + 0, z + 7, BloodCraftMod.DesolatedBrick, 0, 3);
		par1World.setBlock(x + 2, y + 0, z + 7, BloodCraftMod.DesolatedBrick, 0, 3);
		par1World.setBlock(x + 3, y + 0, z + 7, BloodCraftMod.DesolatedBrick, 0, 3);
		par1World.setBlock(x + 4, y + 0, z + 7, BloodCraftMod.DesolatedBrick, 0, 3);
		par1World.setBlock(x + 0, y + 0, z + 8, BloodCraftMod.DesolatedBrick, 0, 3);
		par1World.setBlock(x + 1, y + 0, z + 8, BloodCraftMod.DesolatedBrick, 0, 3);
		par1World.setBlock(x + 2, y + 0, z + 8, BloodCraftMod.DesolatedBrick, 0, 3);
		par1World.setBlock(x + 3, y + 0, z + 8, BloodCraftMod.DesolatedBrick, 0, 3);
		par1World.setBlock(x + 4, y + 0, z + 8, BloodCraftMod.DesolatedBrick, 0, 3);
		par1World.setBlock(x + 0, y + 0, z + 9, BloodCraftMod.DesolatedBrick, 0, 3);
		par1World.setBlock(x + 1, y + 0, z + 9, BloodCraftMod.DesolatedBrick, 0, 3);
		par1World.setBlock(x + 2, y + 0, z + 9, BloodCraftMod.DesolatedBrick, 0, 3);
		par1World.setBlock(x + 3, y + 0, z + 9, BloodCraftMod.DesolatedBrick, 0, 3);
		par1World.setBlock(x + 4, y + 0, z + 9, BloodCraftMod.DesolatedBrick, 0, 3);
		par1World.setBlock(x + 0, y + 1, z + 0, BloodCraftMod.DesolatedBrick, 0, 3);
		par1World.setBlock(x + 1, y + 1, z + 0, Blocks.air, 0, 3);
		par1World.setBlock(x + 2, y + 1, z + 0, Blocks.air, 0, 3);
		par1World.setBlock(x + 3, y + 1, z + 0, Blocks.air, 0, 3);
		par1World.setBlock(x + 4, y + 1, z + 0, BloodCraftMod.DesolatedBrick, 0, 3);
		par1World.setBlock(x + 0, y + 1, z + 1, BloodCraftMod.DesolatedBrick, 0, 3);
		par1World.setBlock(x + 1, y + 1, z + 1, BloodCraftMod.TombStoneB, 0, 3);
		par1World.setBlock(x + 2, y + 1, z + 1, Blocks.air, 0, 3);
		par1World.setBlock(x + 3, y + 1, z + 1, BloodCraftMod.TombStoneB, 0, 3);
		par1World.setBlock(x + 4, y + 1, z + 1, BloodCraftMod.DesolatedBrick, 0, 3);
		par1World.setBlock(x + 0, y + 1, z + 2, BloodCraftMod.DesolatedBrick, 0, 3);
		par1World.setBlock(x + 1, y + 1, z + 2, BloodCraftMod.DesolatedBrick, 0, 3);
		par1World.setBlock(x + 2, y + 1, z + 2, Blocks.air, 0, 3);
		par1World.setBlock(x + 3, y + 1, z + 2, BloodCraftMod.DesolatedBrick, 0, 3);
		par1World.setBlock(x + 4, y + 1, z + 2, BloodCraftMod.DesolatedBrick, 0, 3);
		par1World.setBlock(x + 0, y + 1, z + 3, BloodCraftMod.DesolatedBrick, 0, 3);
		par1World.setBlock(x + 1, y + 1, z + 3, Blocks.cobblestone_wall, 0, 3);
		par1World.setBlock(x + 2, y + 1, z + 3, Blocks.air, 0, 3);
		par1World.setBlock(x + 3, y + 1, z + 3, Blocks.cobblestone_wall, 0, 3);
		par1World.setBlock(x + 4, y + 1, z + 3, BloodCraftMod.DesolatedBrick, 0, 3);
		par1World.setBlock(x + 0, y + 1, z + 4, BloodCraftMod.DesolatedBrick, 0, 3);
		par1World.setBlock(x + 1, y + 1, z + 4, Blocks.air, 0, 3);
		par1World.setBlock(x + 2, y + 1, z + 4, Blocks.air, 0, 3);
		par1World.setBlock(x + 3, y + 1, z + 4, Blocks.air, 0, 3);
		par1World.setBlock(x + 4, y + 1, z + 4, BloodCraftMod.DesolatedBrick, 0, 3);
		par1World.setBlock(x + 0, y + 1, z + 5, BloodCraftMod.DesolatedBrick, 0, 3);
		par1World.setBlock(x + 1, y + 1, z + 5, Blocks.air, 0, 3);
		par1World.setBlock(x + 2, y + 1, z + 5, Blocks.air, 0, 3);
		par1World.setBlock(x + 3, y + 1, z + 5, Blocks.air, 0, 3);
		par1World.setBlock(x + 4, y + 1, z + 5, BloodCraftMod.DesolatedBrick, 0, 3);
		par1World.setBlock(x + 0, y + 1, z + 6, BloodCraftMod.DesolatedBrick, 0, 3);
		par1World.setBlock(x + 1, y + 1, z + 6, Blocks.air, 0, 3);
		par1World.setBlock(x + 2, y + 1, z + 6, Blocks.air, 0, 3);
		par1World.setBlock(x + 3, y + 1, z + 6, Blocks.air, 0, 3);
		par1World.setBlock(x + 4, y + 1, z + 6, BloodCraftMod.DesolatedBrick, 0, 3);
		par1World.setBlock(x + 0, y + 1, z + 7, BloodCraftMod.DesolatedBrick, 0, 3);
		par1World.setBlock(x + 1, y + 1, z + 7, Blocks.air, 0, 3);
		par1World.setBlock(x + 2, y + 1, z + 7, Blocks.air, 0, 3);
		par1World.setBlock(x + 3, y + 1, z + 7, Blocks.air, 0, 3);
		par1World.setBlock(x + 4, y + 1, z + 7, BloodCraftMod.DesolatedBrick, 0, 3);
		par1World.setBlock(x + 0, y + 1, z + 8, BloodCraftMod.DesolatedBrick, 0, 3);
		par1World.setBlock(x + 1, y + 1, z + 8, Blocks.cobblestone_wall, 0, 3);
		par1World.setBlock(x + 2, y + 1, z + 8, Blocks.chest, 3, 3);
		par1World.setBlock(x + 3, y + 1, z + 8, Blocks.cobblestone_wall, 0, 3);
		par1World.setBlock(x + 4, y + 1, z + 8, BloodCraftMod.DesolatedBrick, 0, 3);
		par1World.setBlock(x + 0, y + 1, z + 9, BloodCraftMod.DesolatedBrick, 0, 3);
		par1World.setBlock(x + 1, y + 1, z + 9, BloodCraftMod.DesolatedBrick, 0, 3);
		par1World.setBlock(x + 2, y + 1, z + 9, BloodCraftMod.DesolatedBrick, 0, 3);
		par1World.setBlock(x + 3, y + 1, z + 9, BloodCraftMod.DesolatedBrick, 0, 3);
		par1World.setBlock(x + 4, y + 1, z + 9, BloodCraftMod.DesolatedBrick, 0, 3);
		par1World.setBlock(x + 0, y + 2, z + 0, BloodCraftMod.TombStoneB, 0, 3);
		par1World.setBlock(x + 1, y + 2, z + 0, Blocks.air, 0, 3);
		par1World.setBlock(x + 2, y + 2, z + 0, Blocks.air, 0, 3);
		par1World.setBlock(x + 3, y + 2, z + 0, Blocks.air, 0, 3);
		par1World.setBlock(x + 4, y + 2, z + 0, BloodCraftMod.TombStoneB, 0, 3);
		par1World.setBlock(x + 0, y + 2, z + 1, BloodCraftMod.DesolatedBrick, 0, 3);
		par1World.setBlock(x + 1, y + 2, z + 1, Blocks.air, 0, 3);
		par1World.setBlock(x + 2, y + 2, z + 1, Blocks.air, 0, 3);
		par1World.setBlock(x + 3, y + 2, z + 1, Blocks.air, 0, 3);
		par1World.setBlock(x + 4, y + 2, z + 1, BloodCraftMod.DesolatedBrick, 0, 3);
		par1World.setBlock(x + 0, y + 2, z + 2, BloodCraftMod.DesolatedBrick, 0, 3);
		par1World.setBlock(x + 1, y + 2, z + 2, BloodCraftMod.DesolatedBrick, 0, 3);
		par1World.setBlock(x + 2, y + 2, z + 2, Blocks.air, 0, 3);
		par1World.setBlock(x + 3, y + 2, z + 2, BloodCraftMod.DesolatedBrick, 0, 3);
		par1World.setBlock(x + 4, y + 2, z + 2, BloodCraftMod.DesolatedBrick, 0, 3);
		par1World.setBlock(x + 0, y + 2, z + 3, BloodCraftMod.DesolatedBrick, 0, 3);
		par1World.setBlock(x + 1, y + 2, z + 3, BloodCraftMod.FireBoxOutSide_ON, 0, 3);
		par1World.setBlock(x + 2, y + 2, z + 3, Blocks.air, 0, 3);
		par1World.setBlock(x + 3, y + 2, z + 3, BloodCraftMod.FireBoxOutSide_ON, 0, 3);
		par1World.setBlock(x + 4, y + 2, z + 3, BloodCraftMod.DesolatedBrick, 0, 3);
		par1World.setBlock(x + 0, y + 2, z + 4, BloodCraftMod.DesolatedBrick, 0, 3);
		par1World.setBlock(x + 1, y + 2, z + 4, Blocks.air, 0, 3);
		par1World.setBlock(x + 2, y + 2, z + 4, Blocks.air, 0, 3);
		par1World.setBlock(x + 3, y + 2, z + 4, Blocks.air, 0, 3);
		par1World.setBlock(x + 4, y + 2, z + 4, BloodCraftMod.DesolatedBrick, 0, 3);
		par1World.setBlock(x + 0, y + 2, z + 5, BloodCraftMod.DesolatedBrick, 0, 3);
		par1World.setBlock(x + 1, y + 2, z + 5, Blocks.air, 0, 3);
		par1World.setBlock(x + 2, y + 2, z + 5, Blocks.air, 0, 3);
		par1World.setBlock(x + 3, y + 2, z + 5, Blocks.air, 0, 3);
		par1World.setBlock(x + 4, y + 2, z + 5, BloodCraftMod.DesolatedBrick, 0, 3);
		par1World.setBlock(x + 0, y + 2, z + 6, BloodCraftMod.DesolatedBrick, 0, 3);
		par1World.setBlock(x + 1, y + 2, z + 6, Blocks.air, 0, 3);
		par1World.setBlock(x + 2, y + 2, z + 6, Blocks.air, 0, 3);
		par1World.setBlock(x + 3, y + 2, z + 6, Blocks.air, 0, 3);
		par1World.setBlock(x + 4, y + 2, z + 6, BloodCraftMod.DesolatedBrick, 0, 3);
		par1World.setBlock(x + 0, y + 2, z + 7, BloodCraftMod.DesolatedBrick, 0, 3);
		par1World.setBlock(x + 1, y + 2, z + 7, Blocks.air, 0, 3);
		par1World.setBlock(x + 2, y + 2, z + 7, Blocks.air, 0, 3);
		par1World.setBlock(x + 3, y + 2, z + 7, Blocks.air, 0, 3);
		par1World.setBlock(x + 4, y + 2, z + 7, BloodCraftMod.DesolatedBrick, 0, 3);
		par1World.setBlock(x + 0, y + 2, z + 8, BloodCraftMod.DesolatedBrick, 0, 3);
		par1World.setBlock(x + 1, y + 2, z + 8, BloodCraftMod.FireBoxOutSide_ON, 0, 3);
		par1World.setBlock(x + 2, y + 2, z + 8, Blocks.air, 0, 3);
		par1World.setBlock(x + 3, y + 2, z + 8, BloodCraftMod.FireBoxOutSide_ON, 0, 3);
		par1World.setBlock(x + 4, y + 2, z + 8, BloodCraftMod.DesolatedBrick, 0, 3);
		par1World.setBlock(x + 0, y + 2, z + 9, BloodCraftMod.DesolatedBrick, 0, 3);
		par1World.setBlock(x + 1, y + 2, z + 9, BloodCraftMod.DesolatedBrick, 0, 3);
		par1World.setBlock(x + 2, y + 2, z + 9, BloodCraftMod.DesolatedBrick, 0, 3);
		par1World.setBlock(x + 3, y + 2, z + 9, BloodCraftMod.DesolatedBrick, 0, 3);
		par1World.setBlock(x + 4, y + 2, z + 9, BloodCraftMod.DesolatedBrick, 0, 3);
		par1World.setBlock(x + 0, y + 3, z + 0, Blocks.air, 0, 3);
		par1World.setBlock(x + 1, y + 3, z + 0, Blocks.air, 0, 3);
		par1World.setBlock(x + 2, y + 3, z + 0, Blocks.air, 0, 3);
		par1World.setBlock(x + 3, y + 3, z + 0, Blocks.air, 0, 3);
		par1World.setBlock(x + 4, y + 3, z + 0, Blocks.air, 0, 3);
		par1World.setBlock(x + 0, y + 3, z + 1, BloodCraftMod.DesolatedBrick, 0, 3);
		par1World.setBlock(x + 1, y + 3, z + 1, BloodCraftMod.DesolatedBrick, 0, 3);
		par1World.setBlock(x + 2, y + 3, z + 1, BloodCraftMod.DesolatedBrick, 0, 3);
		par1World.setBlock(x + 3, y + 3, z + 1, BloodCraftMod.DesolatedBrick, 0, 3);
		par1World.setBlock(x + 4, y + 3, z + 1, BloodCraftMod.DesolatedBrick, 0, 3);
		par1World.setBlock(x + 0, y + 3, z + 2, BloodCraftMod.DesolatedBrick, 0, 3);
		par1World.setBlock(x + 1, y + 3, z + 2, BloodCraftMod.DesolatedBrick, 0, 3);
		par1World.setBlock(x + 2, y + 3, z + 2, BloodCraftMod.DesolatedBrick, 0, 3);
		par1World.setBlock(x + 3, y + 3, z + 2, BloodCraftMod.DesolatedBrick, 0, 3);
		par1World.setBlock(x + 4, y + 3, z + 2, BloodCraftMod.DesolatedBrick, 0, 3);
		par1World.setBlock(x + 0, y + 3, z + 3, BloodCraftMod.DesolatedBrick, 0, 3);
		par1World.setBlock(x + 1, y + 3, z + 3, Blocks.air, 0, 3);
		par1World.setBlock(x + 2, y + 3, z + 3, Blocks.air, 0, 3);
		par1World.setBlock(x + 3, y + 3, z + 3, Blocks.air, 0, 3);
		par1World.setBlock(x + 4, y + 3, z + 3, BloodCraftMod.DesolatedBrick, 0, 3);
		par1World.setBlock(x + 0, y + 3, z + 4, BloodCraftMod.DesolatedBrick, 0, 3);
		par1World.setBlock(x + 1, y + 3, z + 4, Blocks.air, 0, 3);
		par1World.setBlock(x + 2, y + 3, z + 4, Blocks.air, 0, 3);
		par1World.setBlock(x + 3, y + 3, z + 4, Blocks.air, 0, 3);
		par1World.setBlock(x + 4, y + 3, z + 4, BloodCraftMod.DesolatedBrick, 0, 3);
		par1World.setBlock(x + 0, y + 3, z + 5, BloodCraftMod.DesolatedBrick, 0, 3);
		par1World.setBlock(x + 1, y + 3, z + 5, Blocks.air, 0, 3);
		par1World.setBlock(x + 2, y + 3, z + 5, Blocks.air, 0, 3);
		par1World.setBlock(x + 3, y + 3, z + 5, Blocks.air, 0, 3);
		par1World.setBlock(x + 4, y + 3, z + 5, BloodCraftMod.DesolatedBrick, 0, 3);
		par1World.setBlock(x + 0, y + 3, z + 6, BloodCraftMod.DesolatedBrick, 0, 3);
		par1World.setBlock(x + 1, y + 3, z + 6, Blocks.air, 0, 3);
		par1World.setBlock(x + 2, y + 3, z + 6, Blocks.air, 0, 3);
		par1World.setBlock(x + 3, y + 3, z + 6, Blocks.air, 0, 3);
		par1World.setBlock(x + 4, y + 3, z + 6, BloodCraftMod.DesolatedBrick, 0, 3);
		par1World.setBlock(x + 0, y + 3, z + 7, BloodCraftMod.DesolatedBrick, 0, 3);
		par1World.setBlock(x + 1, y + 3, z + 7, Blocks.air, 0, 3);
		par1World.setBlock(x + 2, y + 3, z + 7, Blocks.air, 0, 3);
		par1World.setBlock(x + 3, y + 3, z + 7, Blocks.air, 0, 3);
		par1World.setBlock(x + 4, y + 3, z + 7, BloodCraftMod.DesolatedBrick, 0, 3);
		par1World.setBlock(x + 0, y + 3, z + 8, BloodCraftMod.DesolatedBrick, 0, 3);
		par1World.setBlock(x + 1, y + 3, z + 8, Blocks.air, 0, 3);
		par1World.setBlock(x + 2, y + 3, z + 8, Blocks.air, 0, 3);
		par1World.setBlock(x + 3, y + 3, z + 8, Blocks.air, 0, 3);
		par1World.setBlock(x + 4, y + 3, z + 8, BloodCraftMod.DesolatedBrick, 0, 3);
		par1World.setBlock(x + 0, y + 3, z + 9, BloodCraftMod.DesolatedBrick, 0, 3);
		par1World.setBlock(x + 1, y + 3, z + 9, BloodCraftMod.DesolatedBrick, 0, 3);
		par1World.setBlock(x + 2, y + 3, z + 9, BloodCraftMod.DesolatedBrick, 0, 3);
		par1World.setBlock(x + 3, y + 3, z + 9, BloodCraftMod.DesolatedBrick, 0, 3);
		par1World.setBlock(x + 4, y + 3, z + 9, BloodCraftMod.DesolatedBrick, 0, 3);
		par1World.setBlock(x + 0, y + 4, z + 0, Blocks.air, 0, 3);
		par1World.setBlock(x + 1, y + 4, z + 0, Blocks.air, 0, 3);
		par1World.setBlock(x + 2, y + 4, z + 0, Blocks.air, 0, 3);
		par1World.setBlock(x + 3, y + 4, z + 0, Blocks.air, 0, 3);
		par1World.setBlock(x + 4, y + 4, z + 0, Blocks.air, 0, 3);
		par1World.setBlock(x + 0, y + 4, z + 1, Blocks.air, 0, 3);
		par1World.setBlock(x + 1, y + 4, z + 1, Blocks.air, 0, 3);
		par1World.setBlock(x + 2, y + 4, z + 1, Blocks.air, 0, 3);
		par1World.setBlock(x + 3, y + 4, z + 1, Blocks.air, 0, 3);
		par1World.setBlock(x + 4, y + 4, z + 1, Blocks.air, 0, 3);
		par1World.setBlock(x + 0, y + 4, z + 2, Blocks.air, 0, 3);
		par1World.setBlock(x + 1, y + 4, z + 2, BloodCraftMod.DesolatedBrick, 0, 3);
		par1World.setBlock(x + 2, y + 4, z + 2, BloodCraftMod.DesolatedBrick, 0, 3);
		par1World.setBlock(x + 3, y + 4, z + 2, BloodCraftMod.DesolatedBrick, 0, 3);
		par1World.setBlock(x + 4, y + 4, z + 2, Blocks.air, 0, 3);
		par1World.setBlock(x + 0, y + 4, z + 3, Blocks.air, 0, 3);
		par1World.setBlock(x + 1, y + 4, z + 3, BloodCraftMod.DesolatedBrick, 0, 3);
		par1World.setBlock(x + 2, y + 4, z + 3, BloodCraftMod.DesolatedBrick, 0, 3);
		par1World.setBlock(x + 3, y + 4, z + 3, BloodCraftMod.DesolatedBrick, 0, 3);
		par1World.setBlock(x + 4, y + 4, z + 3, Blocks.air, 0, 3);
		par1World.setBlock(x + 0, y + 4, z + 4, Blocks.air, 0, 3);
		par1World.setBlock(x + 1, y + 4, z + 4, BloodCraftMod.DesolatedBrick, 0, 3);
		par1World.setBlock(x + 2, y + 4, z + 4, BloodCraftMod.DesolatedBrick, 0, 3);
		par1World.setBlock(x + 3, y + 4, z + 4, BloodCraftMod.DesolatedBrick, 0, 3);
		par1World.setBlock(x + 4, y + 4, z + 4, Blocks.air, 0, 3);
		par1World.setBlock(x + 0, y + 4, z + 5, Blocks.air, 0, 3);
		par1World.setBlock(x + 1, y + 4, z + 5, BloodCraftMod.DesolatedBrick, 0, 3);
		par1World.setBlock(x + 2, y + 4, z + 5, BloodCraftMod.DesolatedBrick, 0, 3);
		par1World.setBlock(x + 3, y + 4, z + 5, BloodCraftMod.DesolatedBrick, 0, 3);
		par1World.setBlock(x + 4, y + 4, z + 5, Blocks.air, 0, 3);
		par1World.setBlock(x + 0, y + 4, z + 6, Blocks.air, 0, 3);
		par1World.setBlock(x + 1, y + 4, z + 6, BloodCraftMod.DesolatedBrick, 0, 3);
		par1World.setBlock(x + 2, y + 4, z + 6, BloodCraftMod.DesolatedBrick, 0, 3);
		par1World.setBlock(x + 3, y + 4, z + 6, BloodCraftMod.DesolatedBrick, 0, 3);
		par1World.setBlock(x + 4, y + 4, z + 6, Blocks.air, 0, 3);
		par1World.setBlock(x + 0, y + 4, z + 7, Blocks.air, 0, 3);
		par1World.setBlock(x + 1, y + 4, z + 7, BloodCraftMod.DesolatedBrick, 0, 3);
		par1World.setBlock(x + 2, y + 4, z + 7, BloodCraftMod.DesolatedBrick, 0, 3);
		par1World.setBlock(x + 3, y + 4, z + 7, BloodCraftMod.DesolatedBrick, 0, 3);
		par1World.setBlock(x + 4, y + 4, z + 7, Blocks.air, 0, 3);
		par1World.setBlock(x + 0, y + 4, z + 8, Blocks.air, 0, 3);
		par1World.setBlock(x + 1, y + 4, z + 8, BloodCraftMod.DesolatedBrick, 0, 3);
		par1World.setBlock(x + 2, y + 4, z + 8, BloodCraftMod.DesolatedBrick, 0, 3);
		par1World.setBlock(x + 3, y + 4, z + 8, BloodCraftMod.DesolatedBrick, 0, 3);
		par1World.setBlock(x + 4, y + 4, z + 8, Blocks.air, 0, 3);
		par1World.setBlock(x + 0, y + 4, z + 9, Blocks.air, 0, 3);
		par1World.setBlock(x + 1, y + 4, z + 9, Blocks.air, 0, 3);
		par1World.setBlock(x + 2, y + 4, z + 9, Blocks.air, 0, 3);
		par1World.setBlock(x + 3, y + 4, z + 9, Blocks.air, 0, 3);
		par1World.setBlock(x + 4, y + 4, z + 9, Blocks.air, 0, 3);
		par1World.setBlock(x + 0, y + 5, z + 0, Blocks.air, 0, 3);
		par1World.setBlock(x + 1, y + 5, z + 0, Blocks.air, 0, 3);
		par1World.setBlock(x + 2, y + 5, z + 0, Blocks.air, 0, 3);
		par1World.setBlock(x + 3, y + 5, z + 0, Blocks.air, 0, 3);
		par1World.setBlock(x + 4, y + 5, z + 0, Blocks.air, 0, 3);
		par1World.setBlock(x + 0, y + 5, z + 1, Blocks.air, 0, 3);
		par1World.setBlock(x + 1, y + 5, z + 1, Blocks.air, 0, 3);
		par1World.setBlock(x + 2, y + 5, z + 1, Blocks.air, 0, 3);
		par1World.setBlock(x + 3, y + 5, z + 1, Blocks.air, 0, 3);
		par1World.setBlock(x + 4, y + 5, z + 1, Blocks.air, 0, 3);
		par1World.setBlock(x + 0, y + 5, z + 2, Blocks.air, 0, 3);
		par1World.setBlock(x + 1, y + 5, z + 2, Blocks.air, 0, 3);
		par1World.setBlock(x + 2, y + 5, z + 2, Blocks.air, 0, 3);
		par1World.setBlock(x + 3, y + 5, z + 2, Blocks.air, 0, 3);
		par1World.setBlock(x + 4, y + 5, z + 2, Blocks.air, 0, 3);
		par1World.setBlock(x + 0, y + 5, z + 3, Blocks.air, 0, 3);
		par1World.setBlock(x + 1, y + 5, z + 3, Blocks.air, 0, 3);
		par1World.setBlock(x + 2, y + 5, z + 3, BloodCraftMod.TombStoneB, 0, 3);
		par1World.setBlock(x + 3, y + 5, z + 3, Blocks.air, 0, 3);
		par1World.setBlock(x + 4, y + 5, z + 3, Blocks.air, 0, 3);
		par1World.setBlock(x + 0, y + 5, z + 4, Blocks.air, 0, 3);
		par1World.setBlock(x + 1, y + 5, z + 4, Blocks.air, 0, 3);
		par1World.setBlock(x + 2, y + 5, z + 4, Blocks.air, 0, 3);
		par1World.setBlock(x + 3, y + 5, z + 4, Blocks.air, 0, 3);
		par1World.setBlock(x + 4, y + 5, z + 4, Blocks.air, 0, 3);
		par1World.setBlock(x + 0, y + 5, z + 5, Blocks.air, 0, 3);
		par1World.setBlock(x + 1, y + 5, z + 5, Blocks.air, 0, 3);
		par1World.setBlock(x + 2, y + 5, z + 5, Blocks.air, 0, 3);
		par1World.setBlock(x + 3, y + 5, z + 5, Blocks.air, 0, 3);
		par1World.setBlock(x + 4, y + 5, z + 5, Blocks.air, 0, 3);
		par1World.setBlock(x + 0, y + 5, z + 6, Blocks.air, 0, 3);
		par1World.setBlock(x + 1, y + 5, z + 6, Blocks.air, 0, 3);
		par1World.setBlock(x + 2, y + 5, z + 6, Blocks.air, 0, 3);
		par1World.setBlock(x + 3, y + 5, z + 6, Blocks.air, 0, 3);
		par1World.setBlock(x + 4, y + 5, z + 6, Blocks.air, 0, 3);
		par1World.setBlock(x + 0, y + 5, z + 7, Blocks.air, 0, 3);
		par1World.setBlock(x + 1, y + 5, z + 7, Blocks.air, 0, 3);
		par1World.setBlock(x + 2, y + 5, z + 7, BloodCraftMod.TombStoneB, 0, 3);
		par1World.setBlock(x + 3, y + 5, z + 7, Blocks.air, 0, 3);
		par1World.setBlock(x + 4, y + 5, z + 7, Blocks.air, 0, 3);
		par1World.setBlock(x + 0, y + 5, z + 8, Blocks.air, 0, 3);
		par1World.setBlock(x + 1, y + 5, z + 8, Blocks.air, 0, 3);
		par1World.setBlock(x + 2, y + 5, z + 8, Blocks.air, 0, 3);
		par1World.setBlock(x + 3, y + 5, z + 8, Blocks.air, 0, 3);
		par1World.setBlock(x + 4, y + 5, z + 8, Blocks.air, 0, 3);
		par1World.setBlock(x + 0, y + 5, z + 9, Blocks.air, 0, 3);
		par1World.setBlock(x + 1, y + 5, z + 9, Blocks.air, 0, 3);
		par1World.setBlock(x + 2, y + 5, z + 9, Blocks.air, 0, 3);
		par1World.setBlock(x + 3, y + 5, z + 9, Blocks.air, 0, 3);
		par1World.setBlock(x + 4, y + 5, z + 9, Blocks.air, 0, 3);
		
		TileEntityChest entityChest = (TileEntityChest) par1World.getTileEntity(x + 2, y + 1, z + 8);
		if (entityChest != null) {
			//WeightedRandomChestContent.generateChestContents(rand, cryptChestContent, entityChest, 8);
	}
	}
}
